<?xml version="1.0" ?>
<robot name="my_robot" xmlns:xacro="http://www.ros.org/wiki/xacro">




  <xacro:include filename="$(find robot_description)/urdf/robot.gazebo.xacro" />

  <joint name="joint_camera_1" type="fixed">
    <parent link="carcaca"/>
    <child link="camera_1"/>
    <origin rpy="0 1.57 0" xyz="0 0.036515 0.03"/>
  </joint>

  <joint name="joint_lifting_tray" type="prismatic">
    <parent link="carcaca"/>
    <child link="lifting_tray"/>
    <origin rpy="0 0 0" xyz="0 0.07 0.108"/>
    <axis xyz="0 0 1"/>
    <limit effort="10" lower="0" upper="0.10" velocity="0.05"/>
  </joint>

  <joint name="joint_right_wheel" type="revolute">
    <parent link="carcaca"/>
    <child link="right_wheel"/>
    <origin rpy="0     -1.5707  0" xyz="0.19   0.036515  0.04645"/>
    <axis xyz="0   0   -1"/>
    <limit effort="-1.0" lower="-1e+16" upper="1e+16" velocity="-1.0"/>
  </joint>

  <joint name="joint_left_wheel" type="revolute">
    <parent link="carcaca"/>
    <child link="left_wheel"/>
    <origin rpy="0      1.5707  0" xyz="-0.19   0.036515  0.04645"/>
    <axis xyz="0   0   1"/>
    <limit effort="-1.0" lower="-1e+16" upper="1e+16" velocity="-1.0"/>
  </joint>

  <gazebo reference="carcaca">
    <selfCollide>true</selfCollide>
    <mu1 value="0.05"/>
    <mu2 value="0.05"/>
    <kp value="10000000.0" />
    <kd value="1" />
    <fdir1 value="0 0 0"/>
  </gazebo>

  <link name="carcaca">
    <inertial>
      <mass value="20"/>
      <origin rpy="0  0  3.14" xyz="0  0  0"/>
      <inertia ixx="1" ixy="0" ixz="0" iyy="1" iyz="0" izz="1"/>
    </inertial>
    <collision name="carcaca_collision">
      <origin rpy="0  0  3.14" xyz="0  0  0"/>
      <geometry>
        <mesh filename="package://robot_description/models/laser_robot/meshes/carcaca.dae" scale="1 1 1"/>
      </geometry>
    </collision>
    <visual name="carcaca_visual">
      <origin rpy="0  0  3.14" xyz="0  0  0"/>
      <geometry>
        <mesh filename="package://robot_description/models/laser_robot/meshes/carcaca.dae" scale="1.0 1.0 1.0"/>
      </geometry>
    </visual>
  </link>

  <gazebo reference="lifting_tray">
    <selfCollide>true</selfCollide>
    <mu1 value="100"/>
    <mu2 value="50"/>
    <kp value="10000000.0" />
    <kd value="10000" />
    <fdir1 value="0 0 0"/>
  </gazebo>

  <link name="lifting_tray">
    <inertial>
      <mass value="0.5"/>
      <origin rpy="0  0  0" xyz="0  0 0"/>
      <inertia ixx="1" ixy="0" ixz="0" iyy="1" iyz="0" izz="1"/>
    </inertial>
    <collision name="lifting_tray_collision">
      <origin rpy="0  0  0" xyz="0 0 -0.108"/>
      <geometry>
        <mesh filename="package://robot_description/models/laser_robot/meshes/pistao.dae" scale="1 1 1"/>
      </geometry>
    </collision>
    <visual name="lifting_tray_visual">
      <origin rpy="0  0  0" xyz="0 0 -0.108"/>
      <geometry>
        <mesh filename="package://robot_description/models/laser_robot/meshes/pistao.dae" scale="1.0 1.0 1.0"/>
      </geometry>
    </visual>
  </link>

  <link name="camera_1">
    <inertial>
      <mass value="0.1"/>
      <origin rpy="0 1.57 0" xyz="0 0 0.01"/>
      <inertia ixx="1" ixy="0" ixz="0" iyy="1" iyz="0" izz="1"/>
    </inertial>
    <collision name="camera_1_collision">
      <origin rpy="0 1.57 0" xyz="0 0 0"/>
      <geometry>
        <mesh filename="package://robot_description/models/laser_robot/meshes/camera_1.dae" scale="1 1 1"/>
      </geometry>
    </collision>
    <visual name="camera_1_visual">
      <origin rpy="0 1.57 0" xyz="0 0 0"/>
      <geometry>
        <mesh filename="package://robot_description/models/laser_robot/meshes/camera_1.dae" scale="1.0 1.0 1.0"/>
      </geometry>
    </visual>
  </link>

  <gazebo reference="right_wheel">
    <selfCollide>false</selfCollide>
    <mu1 value="100"/>
    <mu2 value="50"/>
    <kp value="10000000.0" />
    <kd value="1" />
    <fdir1 value="1 0 0"/>
  </gazebo>

  <link name="right_wheel">
    <inertial>
      <mass value="1"/>
      <origin rpy="0  0  0" xyz="0  0  0"/>
      <inertia ixx="1" ixy="0" ixz="0" iyy="1" iyz="0" izz="1"/>
    </inertial>
    <collision name="right_wheel_collision">
      <origin rpy="0 0 0" xyz="0 0 0"/> 
      <geometry>
        <mesh filename="package://robot_description/models/laser_robot/meshes/roda.dae" scale="1 1 1"/>
      </geometry>
    </collision>
    <visual name="right_wheel_visual">
      <origin rpy="0 0 0" xyz="0 0 0"/>
      <geometry>
        <mesh filename="package://robot_description/models/laser_robot/meshes/roda.dae" scale="1.0 1.0 1.0"/>
      </geometry>
    </visual>
  </link>


  <gazebo reference="left_wheel">
    <selfCollide>false</selfCollide>
    <mu1 value="100"/>
    <mu2 value="50"/>
    <kp value="10000000.0" />
    <kd value="1" />
    <fdir1 value="1 0 0"/>
  </gazebo>

  <link name="left_wheel">
    <inertial>
      <mass value="1"/>
      <origin rpy="0 0 0" xyz="0 0 0"/>
      <inertia ixx="1" ixy="0" ixz="0" iyy="1" iyz="0" izz="1"/>
    </inertial>
    <collision name="left_wheel_collision">
      <origin rpy="0 0 0" xyz="0 0 0"/>
      <geometry>
        <mesh filename="package://robot_description/models/laser_robot/meshes/roda.dae" scale="1 1 1"/>
      </geometry>
    </collision>
    <visual name="left_wheel_visual">
      <origin rpy="0 0 0" xyz="0 0 0"/>
      <geometry>
        <mesh filename="package://robot_description/models/laser_robot/meshes/roda.dae" scale="1.0 1.0 1.0"/>
      </geometry>
    </visual>
  </link>





</robot>